Traceback (most recent call last):
  File "/Users/smurphy/opt/anaconda3/lib/python3.8/site-packages/jupyter_cache/executors/utils.py", line 51, in single_nb_execution
    executenb(
  File "/Users/smurphy/opt/anaconda3/lib/python3.8/site-packages/nbclient/client.py", line 1087, in execute
    return NotebookClient(nb=nb, resources=resources, km=km, **kwargs).execute()
  File "/Users/smurphy/opt/anaconda3/lib/python3.8/site-packages/nbclient/util.py", line 74, in wrapped
    return just_run(coro(*args, **kwargs))
  File "/Users/smurphy/opt/anaconda3/lib/python3.8/site-packages/nbclient/util.py", line 53, in just_run
    return loop.run_until_complete(coro)
  File "/Users/smurphy/opt/anaconda3/lib/python3.8/asyncio/base_events.py", line 616, in run_until_complete
    return future.result()
  File "/Users/smurphy/opt/anaconda3/lib/python3.8/site-packages/nbclient/client.py", line 540, in async_execute
    await self.async_execute_cell(
  File "/Users/smurphy/opt/anaconda3/lib/python3.8/site-packages/nbclient/client.py", line 832, in async_execute_cell
    self._check_raise_for_error(cell, exec_reply)
  File "/Users/smurphy/opt/anaconda3/lib/python3.8/site-packages/nbclient/client.py", line 740, in _check_raise_for_error
    raise CellExecutionError.from_cell_and_msg(cell, exec_reply['content'])
nbclient.exceptions.CellExecutionError: An error occurred while executing the following cell:
------------------
roughness_length = pd.DataFrame(columns = ['Jan','Feb','Mar','Apr','May','Jun'])

for mon in ['Jan','Feb','Mar','Apr','May','Jun']:
    path = glob.glob('/Volumes/509_data/EddyPro/Output/EddyPro_Runs/FDCorrected_Output/20hz/' + mon + '/eddypro_sonic_essentials_*')
    mean_rl = pd.read_csv(path[0], 
                          index_col = 0)['roughness_length'].mean()
    roughness_length[mon] = [mean_rl]

roughness_length = roughness_length.T
roughness_length.columns = ['z']
print(roughness_length)
------------------

[0;31m---------------------------------------------------------------------------[0m
[0;31mIndexError[0m                                Traceback (most recent call last)
[0;32m<ipython-input-3-885e9693b0e7>[0m in [0;36m<module>[0;34m[0m
[1;32m      3[0m [0;32mfor[0m [0mmon[0m [0;32min[0m [0;34m[[0m[0;34m'Jan'[0m[0;34m,[0m[0;34m'Feb'[0m[0;34m,[0m[0;34m'Mar'[0m[0;34m,[0m[0;34m'Apr'[0m[0;34m,[0m[0;34m'May'[0m[0;34m,[0m[0;34m'Jun'[0m[0;34m][0m[0;34m:[0m[0;34m[0m[0;34m[0m[0m
[1;32m      4[0m     [0mpath[0m [0;34m=[0m [0mglob[0m[0;34m.[0m[0mglob[0m[0;34m([0m[0;34m'/Volumes/509_data/EddyPro/Output/EddyPro_Runs/FDCorrected_Output/20hz/'[0m [0;34m+[0m [0mmon[0m [0;34m+[0m [0;34m'/eddypro_sonic_essentials_*'[0m[0;34m)[0m[0;34m[0m[0;34m[0m[0m
[0;32m----> 5[0;31m     mean_rl = pd.read_csv(path[0], 
[0m[1;32m      6[0m                           index_col = 0)['roughness_length'].mean()
[1;32m      7[0m     [0mroughness_length[0m[0;34m[[0m[0mmon[0m[0;34m][0m [0;34m=[0m [0;34m[[0m[0mmean_rl[0m[0;34m][0m[0;34m[0m[0;34m[0m[0m

[0;31mIndexError[0m: list index out of range
IndexError: list index out of range

